export const catchAsyncErrors = (Err)=>{
      return (req,res,next)=> {
        Promise.resolve(Err(req,res,next)).catch(next)
      }
}